<?xml version='1.0'?>

<robot name="slam_project" xmlns:xacro="http://www.ros.org/wiki/xacro">

  <!--<xacro:include filename="$(find slam_project)/urdf/pan_bot.gazebo" />-->
  <xacro:include filename="$(find slam_project)/urdf/slam_project.gazebo" />


  <material name="Black">
    <color rgba="0.0 0.0 0.0 1.0"/>
  </material>
  <material name="Red">
    <color rgba="0.8 0.0 0.0 1.0"/>
  </material>
  <material name="White">
    <color rgba="1.0 1.0 1.0 1.0"/>
  </material>
  <material name="Blue">
    <color rgba="0.0 0.0 0.8 1.0"/>
  </material>
  <material name="Green">
    <color rgba="0.0 1.0 0.0 1.0"/>
  </material>


  <link name="base_footprint">
  </link>

  <joint name="robot_footprint_joint" type="fixed">
    <origin xyz="0 0 0" rpy="0 0 0" />
    <parent link="base_footprint"/>
    <child link="chassis" />
  </joint>

  <joint type="fixed" name="camera_joint">
    <origin xyz="0.2 0 0" rpy="0 0 0"/>
    <child link="camera_link"/>
    <parent link="chassis"/>
  </joint>


  <link name='camera_link'>
    <visual>
        <origin xyz="0 0 0" rpy="0 0 0"/>
      <geometry>
        <box size=".05 .05 .05"/>
      </geometry>
    </visual>
    <collision name='camera_collision'>
      <origin xyz="0 0 0" rpy="0 0 0"/>
      <geometry>
        <box size=".05 .05 .05"/>
      </geometry>
    </collision>
    <inertial>
      <mass value="0.1"/>
      <origin xyz="0 0 0" rpy="0 0 0"/>
      <inertia
          ixx="1e-6" ixy="0" ixz="0"
          iyy="1e-6" iyz="0"
          izz="1e-6"
      />
    </inertial>
  </link>





  <link name='hokuyo'>
    <visual name='hokuyo_visual'>
      <origin xyz="0 0 0" rpy="0 0 0"/>
      <geometry>
          <mesh filename="package://slam_project/meshes/hokuyo.dae" />
      </geometry>
    </visual>
    <collision name='hokuyo_collision'>
      <origin xyz="0 0 0" rpy="0 0 0"/>
      <geometry>
        <box size=".1 .1 .1"/>
      </geometry>
    </collision>
    <inertial>
      <mass value="0.1"/>
      <origin xyz="0 0 0" rpy="0 0 0"/>
      <inertia
          ixx="1e-6" ixy="0" ixz="0"
          iyy="1e-6" iyz="0"
          izz="1e-6"
      />
    </inertial>
  </link>

  <joint type="fixed" name="hokuyo_joint">
    <origin xyz="0 0 0.12" rpy="0 0 0"/>
    <child link="hokuyo"/>
    <parent link="chassis"/>
    <!--<axis xyz="0 1.0 0" rpy="0 0 0"/>
    <limit effort="10000" velocity="1000"/>
    <joint_properties damping="1.0" friction="1.0"/>-->
  </joint>


  <joint type="continuous" name="left_wheel_hinge">
    <origin xyz="0 0.22 0" rpy="0 0 0"/>
    <child link="left_wheel"/>
    <parent link="chassis"/>
    <axis xyz="0 1 0" rpy="0 0 0"/>
    <limit effort="10000" velocity="1000"/>
    <joint_properties damping="1.0" friction="1.0"/>
  </joint>


  <joint type="continuous" name="right_wheel_hinge">
    <origin xyz="0 -.22 0" rpy="0 0 0"/>
    <child link="right_wheel"/>
    <parent link="chassis"/>
    <axis xyz="0 1 0" rpy="0 0 0"/>
    <limit effort="10000" velocity="1000"/>
    <joint_properties damping="1.0" friction="1.0"/>
  </joint>

  <link name='left_wheel'>
    <visual>
      <origin xyz="0 0 0" rpy="0 1.5707 1.5707"/>
      <geometry>
          <cylinder length="0.05" radius="0.1"/>
      </geometry>
    </visual>
    <collision name='left_wheel_collision'>
        <origin xyz="0 0 0" rpy="0 1.5707 1.5707"/>
      <geometry>
          <cylinder length="0.05" radius="0.1"/>
      </geometry>
    </collision>
    <inertial>
      <mass value="5.0"/>
      <origin xyz="0 0 0" rpy="0 1.5707 1.5707"/>
      <inertia
          ixx="0.1" ixy="0" ixz="0"
          iyy="0.1" iyz="0"
          izz="0.1"
      />
    </inertial>
  </link>

  <link name='right_wheel'>
    <visual>
        <origin xyz="0 0 0" rpy="0 1.5707 1.5707"/>
      <geometry>
          <cylinder length="0.05" radius="0.1"/>
      </geometry>
    </visual>
    <collision name='right_wheel_collision'>
        <origin xyz="0 0 0" rpy="0 1.5707 1.5707"/>
      <geometry>
          <cylinder length="0.05" radius="0.1"/>
      </geometry>
    </collision>
    <inertial>
      <mass value="5.0"/>
      <origin xyz="0 0 0" rpy="0 1.5707 1.5707"/>
      <inertia
          ixx="0.1" ixy="0" ixz="0"
          iyy="0.1" iyz="0"
          izz="0.1"
      />
    </inertial>
  </link>


  <link name="camera_rgbd_frame">
    <inertial>
      <mass value="0.0001" />
      <origin xyz="0 0 0" />
      <inertia ixx="0.0001" ixy="0.0" ixz="0.0"
               iyy="0.0001" iyz="0.0" 
               izz="0.0001" />
    </inertial>
  </link>

  <joint name="camera_rgbd_joint" type="fixed">
    <!--<origin xyz="0.04 0 0.26" rpy="-1.57  0.0 -1.57" />-->
    <origin xyz="0 0 0" rpy="-1.57  0.0 -1.57" />
       <!--origin xyz="0.04 0 0.26" rpy="0 0 0" /-->
    <parent link="camera_link" />
    <child link="camera_rgbd_frame" />
  </joint>

  <link name='chassis'>
    <pose>0 0 0.1 0 0 0</pose>

    <inertial>
      <mass value="15.0"/>
      <origin xyz="0.0 0 0" rpy=" 0 0 0"/>
      <inertia
          ixx="0.1" ixy="0" ixz="0"
          iyy="0.1" iyz="0"
          izz="0.1"
      />
    </inertial>

    <collision name='collision'>
      <origin xyz="0 0 0" rpy=" 0 0 0"/> 
      <geometry>
        <cylinder length="0.1" radius="0.2"/>
      </geometry>
    </collision>

    <visual name='chassis'>
      <origin xyz="0 0 0" rpy=" 0 0 0"/>
      <geometry>
        <cylinder length="0.1" radius="0.2"/>
      </geometry>
    </visual>

    <collision name='tail'>
      <origin xyz="-.15 0 0" rpy=" 0 0 0"/>
      <geometry>
         <box size=".6 .1 .1"/>
      </geometry>
    </collision>

    <visual name='tail_visual'>
      <origin xyz="-.15 0 0" rpy=" 0 0 0"/>
      <geometry>
         <box size=".6 .1 .1"/>
      </geometry>
    </visual>

    <collision name='front_caster_collision'>
      <origin xyz="0.15 0 -0.05" rpy=" 0 0 0"/>
      <geometry>
        <sphere radius="0.05"/>
      </geometry>
      <surface>
        <friction>
          <ode>
            <mu>0</mu>
            <mu2>0</mu2>
            <slip1>0.0</slip1>
            <slip2>0.0</slip2>
          </ode>
        </friction>
      </surface>
    </collision>

    <visual name='front_caster_visual'>
      <origin xyz="0.15 0 -0.05" rpy=" 0 0 0"/>
      <geometry>
        <sphere radius="0.05"/>
      </geometry>
    </visual>

  </link>
  <joint type="fixed" name="back_caster_joint">
    <origin xyz="-0.4 0 -0.05" rpy=" 0 0 0"/>
    <child link="back_caster"/>
    <parent link="chassis"/>
  </joint>
  <link name="back_caster">
    <collision name='back_caster_collision'>
      <origin xyz="0 0 0" rpy=" 0 0 0"/>
      <geometry>
        <sphere radius="0.05"/>
      </geometry>
      <surface>
        <friction>
          <ode>
            <mu>0</mu>
            <mu2>0</mu2>
            <slip1>0.0</slip1>
            <slip2>0.0</slip2>
          </ode>
        </friction>
      </surface>
    </collision>

    <visual name='back_caster_visual'>
        <!--origin xyz="-0.4  0 -0.05" rpy=" 0 0 0"/-->
      <origin xyz="0 0 0" rpy=" 0 0 0"/>
      <geometry>
        <sphere radius="0.05"/>
      </geometry>
    </visual>
    <inertial>
      <mass value="0.4"/>
      <origin xyz="0 0 0" rpy="0 0 0"/>
      <inertia
          ixx="1e-6" ixy="0" ixz="0"
          iyy="1e-6" iyz="0"
          izz="1e-6"
      />
    </inertial>
  </link>

</robot>
